Workbook

Sheet Raw Data
A1: Transaction_ID | B1: Date | C1: Customer_ID | D1: Customer_Name | E1: Product_ID | F1: Product_Name | G1: Category | H1: Quantity | I1: Unit_Price | J1: Payment_Method | K1: Region | L1: Customer_Segment | M1: Customer_Since | N1: Total_Amount | O1: Month_Start | P1: Tenure_Years (DATEDIF) | Q1: Filter_Match_No
A2: TRX0155 | B2: 45393 | C2: CUST023 | D2: Paul Baker | E2: P009 | F2: Monitor | G2: Electronics | H2: 3 | I2: 249.99 | J2: Cash | K2: Central | L2: Basic | M2: 44425 | N2: 749.97 | O2: =DATE(YEAR(B2),MONTH(B2),1) -> 45383 | P2: =DATEDIF(M2,B2,"Y") -> 2 | Q2: =IF(AND(OR(Analysis!$C$5="All",K2=Analysis!$C$5),OR(Analysis!$C$6="All",G2=Analysis!$C$6)),MAX(Q$1:Q1)+1,"") -> 1
A3: TRX0023 | B3: 45396 | C3: CUST013 | D3: Joseph Jackson | E3: P009 | F3: Monitor | G3: Electronics | H3: 3 | I3: 249.99 | J3: Credit Card | K3: Central | L3: Premium | M3: 44575 | N3: 749.97 | O3: =DATE(YEAR(B3),MONTH(B3),1) -> 45383 | P3: =DATEDIF(M3,B3,"Y") -> 2 | Q3: =IF(AND(OR(Analysis!$C$5="All",K3=Analysis!$C$5),OR(Analysis!$C$6="All",G3=Analysis!$C$6)),MAX(Q$1:Q2)+1,"") -> 2
A4: TRX0139 | B4: 45399 | C4: CUST021 | D4: Kevin Scott | E4: P005 | F4: Blender | G4: Appliances | H4: 3 | I4: 59.99 | J4: PayPal | K4: South | L4: Standard | M4: 45262 | N4: 179.97 | O4: =DATE(YEAR(B4),MONTH(B4),1) -> 45383 | P4: =DATEDIF(M4,B4,"Y") -> 0 | Q4: =IF(AND(OR(Analysis!$C$5="All",K4=Analysis!$C$5),OR(Analysis!$C$6="All",G4=Analysis!$C$6)),MAX(Q$1:Q3)+1,"") -> 3
A5: TRX0043 | B5: 45400 | C5: CUST046 | D5: Kathleen Bennett | E5: P005 | F5: Blender | G5: Appliances | H5: 3 | I5: 59.99 | J5: Cash | K5: North | L5: Premium | M5: 45114 | N5: 179.97 | O5: =DATE(YEAR(B5),MONTH(B5),1) -> 45383 | P5: =DATEDIF(M5,B5,"Y") -> 0 | Q5: =IF(AND(OR(Analysis!$C$5="All",K5=Analysis!$C$5),OR(Analysis!$C$6="All",G5=Analysis!$C$6)),MAX(Q$1:Q4)+1,"") -> 4
A6: TRX0212 | B6: 45400 | C6: CUST003 | D6: Michael Brown | E6: P008 | F6: Bookshelf | G6: Furniture | H6: 5 | I6: 149.99 | J6: Credit Card | K6: North | L6: Premium | M6: 45295 | N6: 749.95 | O6: =DATE(YEAR(B6),MONTH(B6),1) -> 45383 | P6: =DATEDIF(M6,B6,"Y") -> 0 | Q6: =IF(AND(OR(Analysis!$C$5="All",K6=Analysis!$C$5),OR(Analysis!$C$6="All",G6=Analysis!$C$6)),MAX(Q$1:Q5)+1,"") -> 5
A7: TRX0092 | B7: 45403 | C7: CUST024 | D7: Dorothy Nelson | E7: P005 | F7: Blender | G7: Appliances | H7: 2 | I7: 59.99 | J7: Cash | K7: West | L7: Standard | M7: 44746 | N7: 119.98 | O7: =DATE(YEAR(B7),MONTH(B7),1) -> 45383 | P7: =DATEDIF(M7,B7,"Y") -> 1 | Q7: =IF(AND(OR(Analysis!$C$5="All",K7=Analysis!$C$5),OR(Analysis!$C$6="All",G7=Analysis!$C$6)),MAX(Q$1:Q6)+1,"") -> 6
A8: TRX0193 | B8: 45403 | C8: CUST024 | D8: Dorothy Nelson | E8: P003 | F8: Headphones | G8: Electronics | H8: 5 | I8: 149.99 | J8: Credit Card | K8: Central | L8: Standard | M8: 44418 | N8: 749.95 | O8: =DATE(YEAR(B8),MONTH(B8),1) -> 45383 | P8: =DATEDIF(M8,B8,"Y") -> 2 | Q8: =IF(AND(OR(Analysis!$C$5="All",K8=Analysis!$C$5),OR(Analysis!$C$6="All",G8=Analysis!$C$6)),MAX(Q$1:Q7)+1,"") -> 7
A9: TRX0240 | B9: 45403 | C9: CUST017 | D9: Charles Allen | E9: P005 | F9: Blender | G9: Appliances | H9: 3 | I9: 59.99 | J9: Debit Card | K9: South | L9: Basic | M9: 45007 | N9: 179.97 | O9: =DATE(YEAR(B9),MONTH(B9),1) -> 45383 | P9: =DATEDIF(M9,B9,"Y") -> 1 | Q9: =IF(AND(OR(Analysis!$C$5="All",K9=Analysis!$C$5),OR(Analysis!$C$6="All",G9=Analysis!$C$6)),MAX(Q$1:Q8)+1,"") -> 8
A10: TRX0135 | B10: 45405 | C10: CUST009 | D10: Robert Thomas | E10: P001 | F10: Laptop | G10: Electronics | H10: 3 | I10: 899.99 | J10: PayPal | K10: East | L10: Standard | M10: 45299 | N10: 2699.97 | O10: =DATE(YEAR(B10),MONTH(B10),1) -> 45383 | P10: =DATEDIF(M10,B10,"Y") -> 0 | Q10: =IF(AND(OR(Analysis!$C$5="All",K10=Analysis!$C$5),OR(Analysis!$C$6="All",G10=Analysis!$C$6)),MAX(Q$1:Q9)+1,"") -> 9
A11: TRX0185 | B11: 45408 | C11: CUST026 | D11: Karen Hill | E11: P005 | F11: Blender | G11: Appliances | H11: 3 | I11: 59.99 | J11: Cash | K11: West | L11: Premium | M11: 45207 | N11: 179.97 | O11: =DATE(YEAR(B11),MONTH(B11),1) -> 45383 | P11: =DATEDIF(M11,B11,"Y") -> 0 | Q11: =IF(AND(OR(Analysis!$C$5="All",K11=Analysis!$C$5),OR(Analysis!$C$6="All",G11=Analysis!$C$6)),MAX(Q$1:Q10)+1,"") -> 10
A12: TRX0138 | B12: 45408 | C12: CUST022 | D12: Susan Green | E12: P008 | F12: Bookshelf | G12: Furniture | H12: 1 | I12: 149.99 | J12: Credit Card | K12: West | L12: Standard | M12: 45103 | N12: 149.99 | O12: =DATE(YEAR(B12),MONTH(B12),1) -> 45383 | P12: =DATEDIF(M12,B12,"Y") -> 0 | Q12: =IF(AND(OR(Analysis!$C$5="All",K12=Analysis!$C$5),OR(Analysis!$C$6="All",G12=Analysis!$C$6)),MAX(Q$1:Q11)+1,"") -> 11
A13: TRX0209 | B13: 45408 | C13: CUST046 | D13: Kathleen Bennett | E13: P008 | F13: Bookshelf | G13: Furniture | H13: 5 | I13: 149.99 | J13: Debit Card | K13: North | L13: Basic | M13: 44830 | N13: 749.95 | O13: =DATE(YEAR(B13),MONTH(B13),1) -> 45383 | P13: =DATEDIF(M13,B13,"Y") -> 1 | Q13: =IF(AND(OR(Analysis!$C$5="All",K13=Analysis!$C$5),OR(Analysis!$C$6="All",G13=Analysis!$C$6)),MAX(Q$1:Q12)+1,"") -> 12
... A251: TRX0064 | B251: 45758 | C251: CUST031 | D251: Steven Turner | E251: P010 | F251: Keyboard | G251: Electronics | H251: 3 | I251: 89.99 | J251: Debit Card | K251: North | L251: Premium | M251: 44878 | N251: 269.97 | O251: =DATE(YEAR(B251),MONTH(B251),1) -> 45748 | P251: =DATEDIF(M251,B251,"Y") -> 2 | Q251: =IF(AND(OR(Analysis!$C$5="All",K251=Analysis!$C$5),OR(Analysis!$C$6="All",G251=Analysis!$C$6)),MAX(Q$1:Q250)+1,"") -> 250

Sheet Analysis
A1: Analysis - Formula Workings (Data Intelligence Dashboard)
A4: 1. Date & Time Functions, Timestamp and Filter Selectors
A5: Filter: Region | C5: All
A6: Filter: Category | C6: All
A7: Today (TODAY) | C7: =TODAY() -> 46310 | E7: Timestamp (NOW + iterative calc)
A8: Now (NOW) | C8: =NOW() -> 46310.46
A9: First transaction date | C9: =MIN('Raw Data'!$B$2:$B$251) -> 45393 | F9: Entry: | G9: Sample entry
A10: Last transaction date | C10: =MAX('Raw Data'!$B$2:$B$251) -> 45758 | F10: Timestamp: | G10: =IF(G9<>"",IF(N(G10)=0,NOW(),G10),"") -> 46310.186
A11: Data span (DATEDIF, months) | C11: =DATEDIF(C9,C10,"M") -> 12
A12: End of last month (EOMONTH) | C12: =EOMONTH(C10,0) -> 45777
A13: End of next month (EOMONTH +1) | C13: =EOMONTH(C10,1) -> 45808
A14: Days since last sale (DATEDIF) | C14: =DATEDIF(C10,C7,"D") -> 552
A16: 2. Summary KPIs
A17: Total Revenue | C17: =SUM('Raw Data'!$N$2:$N$251) -> 229192.47
A18: Total Transactions | C18: =COUNTA('Raw Data'!$A$2:$A$251) -> 250
A19: Average Order Value | C19: =C17/C18 -> 916.76988
A20: Units Sold | C20: =SUM('Raw Data'!$H$2:$H$251) -> 753
A21: Unique Customers | C21: =SUMPRODUCT(1/COUNTIF('Raw Data'!$C$2:$C$251,'Raw Data'!$C$2:$C$251)) -> 50
A22: Filtered Revenue (Region/Category selection) | C22: =SUMIFS('Raw Data'!$N$2:$N$251,'Raw Data'!$K$2:$K$251,IF($C$5="All","*",$C$5),'Raw Data'!$G$2:$G$251,IF($C$6="All","*",$C$6)) -> 229192.47
A23: Filtered Transactions | C23: =COUNTIFS('Raw Data'!$K$2:$K$251,IF($C$5="All","*",$C$5),'Raw Data'!$G$2:$G$251,IF($C$6="All","*",$C$6)) -> 250
A26: 3. Regional Sales (Pivot-style)
A27: Region | B27: Revenue | C27: Transactions | D27: Units | E27: Avg Order | F27: % of Revenue | G27: Rank
A28: Central | B28: =SUMIFS('Raw Data'!$N$2:$N$251,'Raw Data'!$K$2:$K$251,A28) -> 41288.34 | C28: =COUNTIFS('Raw Data'!$K$2:$K$251,A28) -> 54 | D28: =SUMIFS('Raw Data'!$H$2:$H$251,'Raw Data'!$K$2:$K$251,A28) -> 166 | E28: =IFERROR(B28/C28,0) -> 764.59889 | F28: =B28/$C$17 -> 0.18014702 | G28: =RANK(B28,$B$28:$B$32) -> 4
A29: East | B29: =SUMIFS('Raw Data'!$N$2:$N$251,'Raw Data'!$K$2:$K$251,A29) -> 59288.39 | C29: =COUNTIFS('Raw Data'!$K$2:$K$251,A29) -> 48 | D29: =SUMIFS('Raw Data'!$H$2:$H$251,'Raw Data'!$K$2:$K$251,A29) -> 161 | E29: =IFERROR(B29/C29,0) -> 1235.1748 | F29: =B29/$C$17 -> 0.25868385 | G29: =RANK(B29,$B$28:$B$32) -> 1
A30: North | B30: =SUMIFS('Raw Data'!$N$2:$N$251,'Raw Data'!$K$2:$K$251,A30) -> 50808.31 | C30: =COUNTIFS('Raw Data'!$K$2:$K$251,A30) -> 59 | D30: =SUMIFS('Raw Data'!$H$2:$H$251,'Raw Data'!$K$2:$K$251,A30) -> 169 | E30: =IFERROR(B30/C30,0) -> 861.1578 | F30: =B30/$C$17 -> 0.22168403 | G30: =RANK(B30,$B$28:$B$32) -> 2
A31: South | B31: =SUMIFS('Raw Data'!$N$2:$N$251,'Raw Data'!$K$2:$K$251,A31) -> 36398.75 | C31: =COUNTIFS('Raw Data'!$K$2:$K$251,A31) -> 42 | D31: =SUMIFS('Raw Data'!$H$2:$H$251,'Raw Data'!$K$2:$K$251,A31) -> 125 | E31: =IFERROR(B31/C31,0) -> 866.6369 | F31: =B31/$C$17 -> 0.15881303 | G31: =RANK(B31,$B$28:$B$32) -> 5
A32: West | B32: =SUMIFS('Raw Data'!$N$2:$N$251,'Raw Data'!$K$2:$K$251,A32) -> 41408.68 | C32: =COUNTIFS('Raw Data'!$K$2:$K$251,A32) -> 47 | D32: =SUMIFS('Raw Data'!$H$2:$H$251,'Raw Data'!$K$2:$K$251,A32) -> 132 | E32: =IFERROR(B32/C32,0) -> 881.03574 | F32: =B32/$C$17 -> 0.18067208 | G32: =RANK(B32,$B$28:$B$32) -> 3
A33: Total | B33: =SUM(B28:B32) -> 229192.47 | C33: =SUM(C28:C32) -> 250 | D33: =SUM(D28:D32) -> 753 | F33: =SUM(F28:F32) -> 1
A35: 4. Category Sales
A36: Category | B36: Revenue | C36: Transactions | D36: Units | E36: Avg Order | F36: % of Revenue | G36: Rank
A37: Appliances | B37: =SUMIFS('Raw Data'!$N$2:$N$251,'Raw Data'!$G$2:$G$251,A37) -> 8338.74 | C37: =COUNTIFS('Raw Data'!$G$2:$G$251,A37) -> 43 | D37: =SUMIFS('Raw Data'!$H$2:$H$251,'Raw Data'!$G$2:$G$251,A37) -> 126 | E37: =IFERROR(B37/C37,0) -> 193.92419 | F37: =B37/$C$17 -> 0.036383132 | G37: =RANK(B37,$B$37:$B$39) -> 3
A38: Electronics | B38: =SUMIFS('Raw Data'!$N$2:$N$251,'Raw Data'!$G$2:$G$251,A38) -> 171756.05 | C38: =COUNTIFS('Raw Data'!$G$2:$G$251,A38) -> 131 | D38: =SUMIFS('Raw Data'!$H$2:$H$251,'Raw Data'!$G$2:$G$251,A38) -> 395 | E38: =IFERROR(B38/C38,0) -> 1311.1149 | F38: =B38/$C$17 -> 0.74939657 | G38: =RANK(B38,$B$37:$B$39) -> 1
A39: Furniture | B39: =SUMIFS('Raw Data'!$N$2:$N$251,'Raw Data'!$G$2:$G$251,A39) -> 49097.68 | C39: =COUNTIFS('Raw Data'!$G$2:$G$251,A39) -> 76 | D39: =SUMIFS('Raw Data'!$H$2:$H$251,'Raw Data'!$G$2:$G$251,A39) -> 232 | E39: =IFERROR(B39/C39,0) -> 646.02211 | F39: =B39/$C$17 -> 0.2142203 | G39: =RANK(B39,$B$37:$B$39) -> 2
A40: Total | B40: =SUM(B37:B39) -> 229192.47 | C40: =SUM(C37:C39) -> 250 | D40: =SUM(D37:D39) -> 753 | F40: =SUM(F37:F39) -> 1
A43: 5. Product Sales (Most Sold Products)
A44: Product | B44: Revenue | C44: Transactions | D44: Units | E44: Avg Order | F44: % of Revenue | G44: Rank
A45: Laptop | B45: =SUMIFS('Raw Data'!$N$2:$N$251,'Raw Data'!$F$2:$F$251,A45) -> 67499.25 | C45: =COUNTIFS('Raw Data'!$F$2:$F$251,A45) -> 24 | D45: =SUMIFS('Raw Data'!$H$2:$H$251,'Raw Data'!$F$2:$F$251,A45) -> 75 | E45: =IFERROR(B45/C45,0) -> 2812.4688 | F45: =B45/$C$17 -> 0.29450902 | G45: =RANK(B45,$B$45:$B$54) -> 1
A46: Smartphone | B46: =SUMIFS('Raw Data'!$N$2:$N$251,'Raw Data'!$F$2:$F$251,A46) -> 67199.04 | C46: =COUNTIFS('Raw Data'!$F$2:$F$251,A46) -> 31 | D46: =SUMIFS('Raw Data'!$H$2:$H$251,'Raw Data'!$F$2:$F$251,A46) -> 96 | E46: =IFERROR(B46/C46,0) -> 2167.711 | F46: =B46/$C$17 -> 0.29319916 | G46: =RANK(B46,$B$45:$B$54) -> 2
A47: Desk | B47: =SUMIFS('Raw Data'!$N$2:$N$251,'Raw Data'!$F$2:$F$251,A47) -> 23399.22 | C47: =COUNTIFS('Raw Data'!$F$2:$F$251,A47) -> 26 | D47: =SUMIFS('Raw Data'!$H$2:$H$251,'Raw Data'!$F$2:$F$251,A47) -> 78 | E47: =IFERROR(B47/C47,0) -> 899.97 | F47: =B47/$C$17 -> 0.10209419 | G47: =RANK(B47,$B$45:$B$54) -> 3
A48: Monitor | B48: =SUMIFS('Raw Data'!$N$2:$N$251,'Raw Data'!$F$2:$F$251,A48) -> 21999.12 | C48: =COUNTIFS('Raw Data'!$F$2:$F$251,A48) -> 26 | D48: =SUMIFS('Raw Data'!$H$2:$H$251,'Raw Data'!$F$2:$F$251,A48) -> 88 | E48: =IFERROR(B48/C48,0) -> 846.12 | F48: =B48/$C$17 -> 0.095985352 | G48: =RANK(B48,$B$45:$B$54) -> 4
...

Sheet What-If & Regression
A1: What-If Analysis and Linear Regression
A3: A. Scenario Manager (scenario table - choose scenario in C5)
A5: Active scenario (1-3) | C5: 2
A7: Input | B7: Pessimistic (1) | C7: Base (2) | D7: Optimistic (3) | E7: ACTIVE
A8: Sales volume change % | B8: -0.1 | C8: 0 | D8: 0.15 | E8: =CHOOSE($C$5,B8,C8,D8) -> 0
A9: Price change % | B9: -0.05 | C9: 0 | D9: 0.05 | E9: =CHOOSE($C$5,B9,C9,D9) -> 0
A10: Cost of goods (% of revenue) | B10: 0.7 | C10: 0.65 | D10: 0.6 | E10: =CHOOSE($C$5,B10,C10,D10) -> 0.65
A11: Operating expenses ($) | B11: 60000 | C11: 55000 | D11: 50000 | E11: =CHOOSE($C$5,B11,C11,D11) -> 55000
A13: Current Revenue (from data) | E13: =Analysis!C17 -> 229192.47
A14: Projected Revenue | E14: =E13*(1+E8)*(1+E9) -> 229192.47
A15: Cost of goods | E15: =E14*E10 -> 148975.11
A16: Operating expenses | E16: =E11 -> 55000
A17: Projected Profit | E17: =E14-E15-E16 -> 25217.365
A18: Profit margin | E18: =IFERROR(E17/E14,0) -> 0.11002702
A21: Scenario | B21: Revenue | C21: Profit
A22: Pessimistic | B22: =$E$13*(1+B8)*(1+B9) -> 195959.56 | C22: =B22-B22*B10-B11 -> -1212.1314
A23: Base | B23: =$E$13*(1+C8)*(1+C9) -> 229192.47 | C23: =B23-B23*C10-C11 -> 25217.365
A24: Optimistic | B24: =$E$13*(1+D8)*(1+D9) -> 276749.91 | C24: =B24-B24*D10-D11 -> 60699.963
A27: B. Goal Seek (solved with a formula - result is exact)
A29: Target total revenue ($) | C29: 275000
A30: Current total revenue | C30: =Analysis!C17 -> 229192.47
A31: Required increase in sales volume | C31: =C29/C30-1 -> 0.1998649
A32: Required price (avg order) if volume fixed | C32: =Analysis!C19*C29/C30 -> 1100
A33: Check: revenue after change | C33: =C30*(1+C31) -> 275000
A36: C. Linear Regression: Monthly Revenue vs Month number (SLOPE / INTERCEPT / RSQ / LINEST)
A37: Month # | B37: Month | C37: Revenue (Y) | D37: Predicted | E37: Residual
A38: 1 | B38: =Analysis!A74 -> 45383 | C38: =Analysis!C74 -> 20919.33 | D38: =$C$52+$C$51*A38 -> 17640.446 | E38: =C38-D38 -> 3278.8842
A39: 2 | B39: =Analysis!A75 -> 45413 | C39: =Analysis!C75 -> 17039.35 | D39: =$C$52+$C$51*A39 -> 17799.95 | E39: =C39-D39 -> -760.60017
A40: 3 | B40: =Analysis!A76 -> 45444 | C40: =Analysis!C76 -> 19299.45 | D40: =$C$52+$C$51*A40 -> 17959.455 | E40: =C40-D40 -> 1339.9954
A41: 4 | B41: =Analysis!A77 -> 45474 | C41: =Analysis!C77 -> 18479.4 | D41: =$C$52+$C$51*A41 -> 18118.959 | E41: =C41-D41 -> 360.44101
A42: 5 | B42: =Analysis!A78 -> 45505 | C42: =Analysis!C78 -> 15759.43 | D42: =$C$52+$C$51*A42 -> 18278.463 | E42: =C42-D42 -> -2519.0334
A43: 6 | B43: =Analysis!A79 -> 45536 | C43: =Analysis!C79 -> 12989.51 | D43: =$C$52+$C$51*A43 -> 18437.968 | E43: =C43-D43 -> -5448.4578
A44: 7 | B44: =Analysis!A80 -> 45566 | C44: =Analysis!C80 -> 20609.52 | D44: =$C$52+$C$51*A44 -> 18597.472 | E44: =C44-D44 -> 2012.0478
A45: 8 | B45: =Analysis!A81 -> 45597 | C45: =Analysis!C81 -> 12309.44 | D45: =$C$52+$C$51*A45 -> 18756.977 | E45: =C45-D45 -> -6447.5366
A46: 9 | B46: =Analysis!A82 -> 45627 | C46: =Analysis!C82 -> 23039.3 | D46: =$C$52+$C$51*A46 -> 18916.481 | E46: =C46-D46 -> 4122.819
A47: 10 | B47: =Analysis!A83 -> 45658 | C47: =Analysis!C83 -> 25799.15 | D47: =$C$52+$C$51*A47 -> 19075.985 | E47: =C47-D47 -> 6723.1646
A48: 11 | B48: =Analysis!A84 -> 45689 | C48: =Analysis!C84 -> 16069.38 | D48: =$C$52+$C$51*A48 -> 19235.49 | E48: =C48-D48 -> -3166.1098
A49: 12 | B49: =Analysis!A85 -> 45717 | C49: =Analysis!C85 -> 19899.38 | D49: =$C$52+$C$51*A49 -> 19394.994 | E49: =C49-D49 -> 504.38577
A51: Slope (revenue change per month) | C51: =SLOPE(C38:C49,A38:A49) -> 159.50441
A52: Intercept | C52: =INTERCEPT(C38:C49,A38:A49) -> 17480.941
...

Sheet Visualizations
A1: Visualizations - Additional Charts

Sheet Dashboard
A1: DATA INTELLIGENCE DASHBOARD | Q1: ="Report date: "&TEXT(Analysis!C7,"dd-mmm-yyyy") -> Report date: 15-Oct-2026
A3: ="Customer transaction analysis | Data period: "&TEXT(Analysis!C9,"dd-mmm-yyyy")&" to "&TEXT(Analysis!C10,"dd-mmm-yyyy") -> Customer transaction analysis | Data period: 11-Apr-2024 to 11-Apr-2025
A4: FILTERS > | D4: ="Region: "&Analysis!C5 -> Region: All | G4: ="Category: "&Analysis!C6 -> Category: All
A7: TOTAL REVENUE | E7: TRANSACTIONS | I7: AVG ORDER VALUE | M7: CUSTOMERS | Q7: FILTERED REVENUE | U7: TOP REGION
A8: =Analysis!C17 -> 229192.47 | E8: =Analysis!C18 -> 250 | I8: =Analysis!C19 -> 916.76988 | M8: =Analysis!C21 -> 50 | Q8: =Analysis!C22 -> 229192.47 | U8: =INDEX(Analysis!A28:A32,MATCH(1,Analysis!G28:G32,0)) -> East
A10: ="from "&Analysis!C18&" orders" -> from 250 orders | E10: ="Units sold: "&TEXT(Analysis!C20,"#,##0") -> Units sold: 753 | I10: per transaction | M10: ="Repeat rate "&TEXT(Analysis!C161,"0%") -> Repeat rate 94% | Q10: ="Selected: "&Analysis!C5&" / "&Analysis!C6 -> Selected: All / All | U10: =TEXT(MAX(Analysis!B28:B32),"$#,##0")&" revenue" -> $59,288 revenue
A12: KPI INDICATORS (vs Target) | M12: TOP 5 CUSTOMERS
A13: KPI | E13: Actual | G13: Target | I13: % of Target | K13: Status | M13: # | N13: Customer | S13: Revenue | V13: Share
A14: Total Revenue | E14: =Analysis!C17 -> 229192.47 | G14: 250000 | I14: =E14/G14 -> 0.91676988 | K14: =I14 -> 0.91676988 | M14: 1 | N14: =Analysis!B145 -> Mark Carter | S14: =Analysis!C145 -> 15659.65 | V14: =Analysis!E145 -> 0.068325325
A15: Avg Order Value | E15: =Analysis!C19 -> 916.76988 | G15: 900 | I15: =E15/G15 -> 1.0186332 | K15: =I15 -> 1.0186332 | M15: 2 | N15: =Analysis!B146 -> Edward Mitchell | S15: =Analysis!C146 -> 11919.77 | V15: =Analysis!E146 -> 0.052007686
A16: Repeat Customer Rate | E16: =Analysis!C161 -> 0.94 | G16: 0.9 | I16: =E16/G16 -> 1.0444444 | K16: =I16 -> 1.0444444 | M16: 3 | N16: =Analysis!B147 -> Barbara Young | S16: =Analysis!C147 -> 10649.8 | V16: =Analysis!E147 -> 0.046466623
A17: Transactions | E17: =Analysis!C18 -> 250 | G17: 350 | I17: =E17/G17 -> 0.71428571 | K17: =I17 -> 0.71428571 | M17: 4 | N17: =Analysis!B148 -> Patricia Moore | S17: =Analysis!C148 -> 9799.73 | V17: =Analysis!E148 -> 0.042757644
M18: 5 | N18: =Analysis!B149 -> Paul Baker | S18: =Analysis!C149 -> 8309.74 | V18: =Analysis!E149 -> 0.036256601
A20: SALES ANALYSIS
A53: REGION x CATEGORY REVENUE (heatmap) | M53: KEY INSIGHTS
A54: Region | D54: Appliances | F54: Electronics | H54: Furniture | J54: Total | M54: =Report!C5 -> Total revenue of $229,192 came from 250 transactions by 50 customers (average order $917).
A55: =Analysis!A28 -> Central | D55: =SUMIFS('Raw Data'!$N$2:$N$251,'Raw Data'!$K$2:$K$251,$A55,'Raw Data'!$G$2:$G$251,"Appliances") -> 1999.71 | F55: =SUMIFS('Raw Data'!$N$2:$N$251,'Raw Data'!$K$2:$K$251,$A55,'Raw Data'!$G$2:$G$251,"Electronics") -> 24889.33 | H55: =SUMIFS('Raw Data'!$N$2:$N$251,'Raw Data'!$K$2:$K$251,$A55,'Raw Data'!$G$2:$G$251,"Furniture") -> 14399.3 | J55: =SUM(D55:I55) -> 41288.34 | M55: =Report!C6 -> Top customer is Mark Carter ($15,660). The top 10 customers contribute 41% of revenue.
A56: =Analysis!A29 -> East | D56: =SUMIFS('Raw Data'!$N$2:$N$251,'Raw Data'!$K$2:$K$251,$A56,'Raw Data'!$G$2:$G$251,"Appliances") -> 2239.67 | F56: =SUMIFS('Raw Data'!$N$2:$N$251,'Raw Data'!$K$2:$K$251,$A56,'Raw Data'!$G$2:$G$251,"Electronics") -> 50649.01 | H56: =SUMIFS('Raw Data'!$N$2:$N$251,'Raw Data'!$K$2:$K$251,$A56,'Raw Data'!$G$2:$G$251,"Furniture") -> 6399.71 | J56: =SUM(D56:I56) -> 59288.39 | M56: =Report!C7 -> Most frequently purchased: Bookshelf (35 transactions). Highest revenue product: Laptop.
A57: =Analysis!A30 -> North | D57: =SUMIFS('Raw Data'!$N$2:$N$251,'Raw Data'!$K$2:$K$251,$A57,'Raw Data'!$G$2:$G$251,"Appliances") -> 1119.84 | F57: =SUMIFS('Raw Data'!$N$2:$N$251,'Raw Data'!$K$2:$K$251,$A57,'Raw Data'!$G$2:$G$251,"Electronics") -> 39239.04 | H57: =SUMIFS('Raw Data'!$N$2:$N$251,'Raw Data'!$K$2:$K$251,$A57,'Raw Data'!$G$2:$G$251,"Furniture") -> 10449.43 | J57: =SUM(D57:I57) -> 50808.31 | M57: =Report!C8 -> Best region: East ($59,288). Weakest: South ($36,399).
A58: =Analysis!A31 -> South | D58: =SUMIFS('Raw Data'!$N$2:$N$251,'Raw Data'!$K$2:$K$251,$A58,'Raw Data'!$G$2:$G$251,"Appliances") -> 1099.83 | F58: =SUMIFS('Raw Data'!$N$2:$N$251,'Raw Data'!$K$2:$K$251,$A58,'Raw Data'!$G$2:$G$251,"Electronics") -> 25549.32 | H58: =SUMIFS('Raw Data'!$N$2:$N$251,'Raw Data'!$K$2:$K$251,$A58,'Raw Data'!$G$2:$G$251,"Furniture") -> 9749.6 | J58: =SUM(D58:I58) -> 36398.75 | M58: =Report!C9 -> Electronics is the leading category with 75% of revenue.
A59: =Analysis!A32 -> West | D59: =SUMIFS('Raw Data'!$N$2:$N$251,'Raw Data'!$K$2:$K$251,$A59,'Raw Data'!$G$2:$G$251,"Appliances") -> 1879.69 | F59: =SUMIFS('Raw Data'!$N$2:$N$251,'Raw Data'!$K$2:$K$251,$A59,'Raw Data'!$G$2:$G$251,"Electronics") -> 31429.35 | H59: =SUMIFS('Raw Data'!$N$2:$N$251,'Raw Data'!$K$2:$K$251,$A59,'Raw Data'!$G$2:$G$251,"Furniture") -> 8099.64 | J59: =SUM(D59:I59) -> 41408.68 | M59: =Report!C13 -> Focus marketing on High-Value customers, bundle Electronics with Furniture (cross-sell), and replicate best-region practices in the weakest region.

Sheet Report
B1: Final Report - Insights & Storytelling
B4: Topic | C4: Insight
B5: Total Revenue | C5: ="Total revenue of "&TEXT(Analysis!C17,"$#,##0")&" came from "&Analysis!C18&" transactions by "&Analysis!C21&" customers (average order "&TEXT(Analysis!C19,"$#,##0")&")." -> Total revenue of $229,192 came from 250 transactions by 50 customers (average order $917).
B6: Top Customers | C6: ="Top customer is "&Analysis!B145&" ("&TEXT(Analysis!C145,"$#,##0")&"). The top 10 customers contribute "&TEXT(SUM(Analysis!E145:E154),"0%")&" of revenue." -> Top customer is Mark Carter ($15,660). The top 10 customers contribute 41% of revenue.
B7: Most Sold Products | C7: ="Most frequently purchased: "&Analysis!C157&" ("&Analysis!C158&" transactions). Highest revenue product: "&Analysis!C159&"." -> Most frequently purchased: Bookshelf (35 transactions). Highest revenue product: Laptop.
B8: Regional Sales | C8: ="Best region: "&INDEX(Analysis!A28:A32,MATCH(1,Analysis!G28:G32,0))&" ("&TEXT(MAX(Analysis!B28:B32),"$#,##0")&"). Weakest: "&INDEX(Analysis!A28:A32,MATCH(MAX(Analysis!G28:G32),Analysis!G28:G32,0))&" ("&TEXT(MIN(Analysis!B28:B32),"$#,##0")&")." -> Best region: East ($59,288). Weakest: South ($36,399).
B9: Category Mix | C9: =INDEX(Analysis!A37:A39,MATCH(1,Analysis!G37:G39,0))&" is the leading category with "&TEXT(MAX(Analysis!F37:F39),"0%")&" of revenue." -> Electronics is the leading category with 75% of revenue.
B10: Customer Loyalty | C10: =Analysis!C160&" of "&Analysis!C21&" customers ("&TEXT(Analysis!C161,"0%")&") bought more than once; "&Analysis!C163&" bought both Electronics and Furniture." -> 47 of 50 customers (94%) bought more than once; 34 bought both Electronics and Furniture.
B11: Trend | C11: ='What-If & Regression'!A60 -> 0
B12: Forecast | C12: ="Linear forecast for the next two months: "&TEXT('What-If & Regression'!C56,"$#,##0")&" and "&TEXT('What-If & Regression'!C57,"$#,##0")&"." -> Linear forecast for the next two months: $19,554 and $19,714.
B13: Recommendation | C13: Focus marketing on High-Value customers, bundle Electronics with Furniture (cross-sell), and replicate best-region practices in the weakest region.
